<?xml version="1.0"?>
<robot xmlns:xacro="http://www.ros.org/wiki/xacro">

  <link name="base_footprint"></link>
  <joint name="base_footprint_joint" type="fixed">
    <parent link="base_footprint"/>
    <child link="base_link"/>
    <origin xyz="0 0 0" rpy="0 0 0"/>
  </joint>

  <link
    name="base_link">
    <inertial>
      <origin
        xyz="-0.020088 -9.2937E-05 0.02136"
        rpy="0 0 0" />
      <mass
        value="2.4154" />
      <inertia
        ixx="0.0062254"
        ixy="3.3866E-07"
        ixz="0.00015974"
        iyy="0.0043358"
        iyz="-3.09E-06"
        izz="0.0097947" />
    </inertial>
    <visual>
      <origin
        xyz="0 0 0"
        rpy="0 0 0" />
      <geometry>
        <mesh
          filename="dshape_description/meshes/base_link.STL" />
      </geometry>
      <material
        name="">
        <color
          rgba="0 0 0 1" />
      </material>
    </visual>
    <collision>
      <origin
        xyz="0 0 0"
        rpy="0 0 0" />
      <geometry>
        <mesh
          filename="dshape_description/meshes/base_link.STL" />
      </geometry>
    </collision>
  </link>
  <link
    name="right_wheel">
    <inertial>
      <origin
        xyz="-6.6265E-06 -4.8357E-05 1.088E-05"
        rpy="0 0 0" />
      <mass
        value="0.017988" />
      <inertia
        ixx="1.232E-05"
        ixy="-1.1651E-10"
        ixz="-1.2027E-09"
        iyy="2.4408E-05"
        iyz="2.0648E-10"
        izz="1.2322E-05" />
    </inertial>
    <visual>
      <origin
        xyz="0 0 0"
        rpy="0 0 0" />
      <geometry>
        <mesh
          filename="dshape_description/meshes/right_wheel.STL" />
      </geometry>
      <material
        name="">
        <color
          rgba="0.29804 0.29804 0.29804 1" />
      </material>
    </visual>
    <collision>
      <origin
        xyz="0 0 0"
        rpy="0 0 0" />
      <geometry>
        <mesh
          filename="dshape_description/meshes/right_wheel.STL" />
      </geometry>
    </collision>
  </link>
  <joint
    name="right_wheel_joint"
    type="continuous">
    <origin
      xyz="-0.037981 -0.11991 -0.011849"
      rpy="0 0 0" />
    <parent
      link="base_link" />
    <child
      link="right_wheel" />
    <axis
      xyz="0 1 0" />
  </joint>
  <link
    name="left_wheel">
    <inertial>
      <origin
        xyz="6.6265E-06 4.8357E-05 1.088E-05"
        rpy="0 0 0" />
      <mass
        value="0.017988" />
      <inertia
        ixx="1.232E-05"
        ixy="-1.1651E-10"
        ixz="1.2027E-09"
        iyy="2.4408E-05"
        iyz="-2.0648E-10"
        izz="1.2322E-05" />
    </inertial>
    <visual>
      <origin
        xyz="0 0 0"
        rpy="0 0 0" />
      <geometry>
        <mesh
          filename="dshape_description/meshes/left_wheel.STL" />
      </geometry>
      <material
        name="">
        <color
          rgba="0.29804 0.29804 0.29804 1" />
      </material>
    </visual>
    <collision>
      <origin
        xyz="0 0 0"
        rpy="0 0 0" />
      <geometry>
        <mesh
          filename="dshape_description/meshes/left_wheel.STL" />
      </geometry>
    </collision>
  </link>
  <joint
    name="left_wheel_joint"
    type="continuous">
    <origin
      xyz="-0.03813 0.11892 -0.011747"
      rpy="0 0 0" />
    <parent
      link="base_link" />
    <child
      link="left_wheel" />
    <axis
      xyz="0 1 0" />
  </joint>

  <!-- lidar -->
  <link name="lidar"></link>
  <joint name="lidar_joint" type="fixed">
    <parent link="base_link"/>
    <child link="lidar"/>
    <origin xyz="0 0 0.02" rpy="0 0 0"/>
  </joint>

  <link name="camera"></link>
  <joint name="camera_joint" type="fixed">
    <parent link="base_link"/>
    <child link="camera"/>
    <origin xyz="0 0 0.03" rpy="0 0 0"/>
  </joint>


  <!-- Colour -->
  <gazebo reference="base_link">
    <material>Gazebo/Black</material>
  </gazebo>

  <gazebo reference="right_wheel">
    <material>Gazebo/Yellow</material>
  </gazebo>

   <gazebo reference="left_wheel">
    <material>Gazebo/Yellow</material>
  </gazebo>

   <gazebo reference="lidar">
    <material>Gazebo/White</material>
  </gazebo>
</robot>