<?xml version="1.0" encoding="utf-8"?>
<!-- This URDF was automatically created by SolidWorks to URDF Exporter! Originally created by Stephen Brawner (brawner@gmail.com) 
     Commit Version: 1.6.0-1-g15f4949  Build Version: 1.6.7594.29634
     For more information, please see http://wiki.ros.org/sw_urdf_exporter -->
<robot
  name="dshape">
  <link
    name="base_link">
    <inertial>
      <origin
        xyz="-0.020088 -9.2937E-05 0.02136"
        rpy="0 0 0" />
      <mass
        value="2.4154" />
      <inertia
        ixx="0.0062254"
        ixy="3.3866E-07"
        ixz="0.00015974"
        iyy="0.0043358"
        iyz="-3.09E-06"
        izz="0.0097947" />
    </inertial>
    <visual>
      <origin
        xyz="0 0 0"
        rpy="0 0 0" />
      <geometry>
        <mesh
          filename="dshape_description/meshes/base_link.STL" />
      </geometry>
      <material
        name="">
        <color
          rgba="0 0 0 1" />
      </material>
    </visual>
    <collision>
      <origin
        xyz="0 0 0"
        rpy="0 0 0" />
      <geometry>
        <mesh
          filename="dshape_description/meshes/base_link.STL" />
      </geometry>
    </collision>
  </link>
  <link
    name="right_wheel">
    <inertial>
      <origin
        xyz="-6.6265E-06 -4.8357E-05 1.088E-05"
        rpy="0 0 0" />
      <mass
        value="0.017988" />
      <inertia
        ixx="1.232E-05"
        ixy="-1.1651E-10"
        ixz="-1.2027E-09"
        iyy="2.4408E-05"
        iyz="2.0648E-10"
        izz="1.2322E-05" />
    </inertial>
    <visual>
      <origin
        xyz="0 0 0"
        rpy="0 0 0" />
      <geometry>
        <mesh
          filename="dshape_description/meshes/right_wheel.STL" />
      </geometry>
      <material
        name="">
        <color
          rgba="0.29804 0.29804 0.29804 1" />
      </material>
    </visual>
    <collision>
      <origin
        xyz="0 0 0"
        rpy="0 0 0" />
      <geometry>
        <mesh
          filename="dshape_description/meshes/right_wheel.STL" />
      </geometry>
    </collision>
  </link>
  <joint
    name="right_wheel_joint"
    type="continuous">
    <origin
      xyz="-0.037981 -0.11991 -0.011849"
      rpy="0 0 0" />
    <parent
      link="base_link" />
    <child
      link="right_wheel" />
    <axis
      xyz="0 1 0" />
  </joint>
  <link
    name="left_wheel">
    <inertial>
      <origin
        xyz="6.6265E-06 4.8357E-05 1.088E-05"
        rpy="0 0 0" />
      <mass
        value="0.017988" />
      <inertia
        ixx="1.232E-05"
        ixy="-1.1651E-10"
        ixz="1.2027E-09"
        iyy="2.4408E-05"
        iyz="-2.0648E-10"
        izz="1.2322E-05" />
    </inertial>
    <visual>
      <origin
        xyz="0 0 0"
        rpy="0 0 0" />
      <geometry>
        <mesh
          filename="dshape_description/meshes/left_wheel.STL" />
      </geometry>
      <material
        name="">
        <color
          rgba="0.29804 0.29804 0.29804 1" />
      </material>
    </visual>
    <collision>
      <origin
        xyz="0 0 0"
        rpy="0 0 0" />
      <geometry>
        <mesh
          filename="dshape_description/meshes/left_wheel.STL" />
      </geometry>
    </collision>
  </link>
  <joint
    name="left_wheel_joint"
    type="continuous">
    <origin
      xyz="-0.03813 0.11892 -0.011747"
      rpy="0 0 0" />
    <parent
      link="base_link" />
    <child
      link="left_wheel" />
    <axis
      xyz="0 1 0" />
  </joint>
</robot>